# 1.7 错误和异常

## 1.7.1 错误处理策略

Go语言中的导出函数一般不抛出异常，一个未受控的异常可以看作是程序的BUG。

但是对于那些提供类似Web服务的框架而言；它们经常需要接入第三方的中间件。因为第三方的中间件是否存在BUG是否会抛出异常，Web框架本身是不能确定的。

为了提高系统的稳定性，Web框架一般会通过`recover`来防御性地捕获所有处理流程中可能产生的异常，然后将异常转为普通的错误返回。

让我们以 JSON 解析器为例，说明 recover 的使用场景。考虑到 JSON 解析器的复杂性，即使某个语言解析器目前工作正常，也无法肯定它没有漏洞。因此，当某个异常出现时，我们不会选择让解析器崩溃，而是会将 panic 异常当作普通的解析错误，并附加额外信息提醒用户报告此错误。

```go
func ParseJSON(input string) (s *Syntax, err error) {
    defer func() {
        if p := recover(); p != nil {
            err = fmt.Errorf("JSON: internal error: %v", p)
        }
    }()
    // ...parser...
}
```

标准库中的 `json` 包，在内部递归解析 JSON 数据的时候如果遇到错误，会通过抛出异常的方式来快速跳出深度嵌套的函数调用，然后由最外一级的接口通过 `recover` 捕获 `panic` ，然后返回相应的错误信息。

Go 语言库的实现习惯: 即使在包内部使用了 `panic` ，但是在导出函数时会被转化为明确的错误值。

## 1.7.2 获取错误的上下文

书里自己包装了一份 error 结构，用于给错误增加调用栈信息，同时支持错误的多级嵌套包装，支持错误码格式。在 `github.com/chai2010/errors` 包，里面是以下的错误类型：

```go
type Error interface {
    Caller() []CallerInfo
    Wraped() []error
    Code() int
    error

    private()
}

type CallerInfo struct {
    FuncName string
    FileName string
    FileLine int
}
```

一些使用例子及解释可以参考 [错误和异常](https://chai2010.cn/advanced-go-programming-book/ch1-basic/ch1-07-error-and-panic.html) 。



## 1.7.3 错误的错误返回

Go语言中的错误是一种接口类型。定义如下：

```go
// The error built-in interface type is the conventional interface for
// representing an error condition, with the nil value representing no error.
type error interface {
	Error() string
}
```

接口信息中包含了原始类型和原始的值。只有当**接口的类型和原始的值都为空**的时候，接口的值才对应`nil`。其实当接口中类型为空的时候，原始值必然也是空的；反之，当接口对应的原始值为空的时候，接口对应的原始类型并不一定为空的。

在下面的例子中，试图返回自定义的错误类型，当没有错误的时候返回 `nil`：

```go
func returnsError() error {
    var p *MyError = nil
    if bad() {
        p = ErrBad
    }
    return p // Will always return a non-nil error.
}
```

但是，最终返回的结果其实并非是 `nil`：是一个正常的错误，错误的值是一个 `MyError` 类型的空指针。下面是改进的 `returnsError` ：

```go
func returnsError() error {
    if bad() {
        return (*MyError)(err)
    }
    return nil
}
```

因此，在处理错误返回值的时候，没有错误的返回值最好直接写为`nil`。

## 1.7.4 剖析异常

可能会犯的错：在非 `defer` 语句中执行 `recover` 调用：

```go
func main() {
    if r := recover(); r != nil {
        log.Fatal(r)
    }

    panic(123)

    if r := recover(); r != nil {
        log.Fatal(r)
    }
}
```

上面程序中两个 `recover` 调用都不能捕获任何异常。在第一个 `recover` 调用执行时，函数必然是在正常的非异常执行流程中，这时候 `recover` 调用将返回`nil`。发生异常时，第二个 `recover` 调用将没有机会被执行到，因为 `panic` 调用会导致函数马上执行已经注册 `defer` 的函数后返回。

其实 `recover` 函数调用有着更严格的要求：我们必须在 **`defer` 函数**中**直接调用`recover`**。如果 `defer` 中调用的是 `recover` 函数的包装函数的话，异常的捕获工作将失败！比如，有时候我们可能希望包装自己的 `MyRecover` 函数，在内部增加必要的日志信息然后再调用 `recover` ，这是错误的做法：

```go
func main() {
    defer func() {
        // 无法捕获异常
        if r := MyRecover(); r != nil {
            fmt.Println(r)
        }
    }()
    panic(1)
}

func MyRecover() interface{} {
    log.Println("trace...")
    return recover()
}
```

同样，如果是在嵌套的 `defer` 函数中调用 `recover` 也将导致无法捕获异常：

```go
func main() {
    defer func() {
        defer func() {
            // 无法捕获异常
            if r := recover(); r != nil {
                fmt.Println(r)
            }
        }()
    }()
    panic(1)
}
```

2 层嵌套的 `defer` 函数中直接调用 `recover` 和 1 层 `defer` 函数中调用包装的 `MyRecover` 函数一样，都是经过了 2 个函数帧才到达真正的 `recover` 函数，这个时候 Goroutine 的对应上一级栈帧中已经没有异常信息。

如果我们直接在 `defer` 语句中调用 `MyRecover` 函数又可以正常工作了：

```go
func MyRecover() interface{} {
    return recover()
}

func main() {
    // 可以正常捕获异常
    defer MyRecover()
    panic(1)
}
```

但是，如果 `defer` 语句直接调用 `recover` 函数，依然不能正常捕获异常：

```go
func main() {
    // 无法捕获异常
    defer recover()
    panic(1)
}
```

**必须要和有异常的栈帧只隔一个栈帧，`recover` 函数才能正常捕获异常**。换言之，`recover `函数捕获的是祖父一级调用函数栈帧的异常（刚好可以跨越一层 `defer` 函数）！



当然，为了避免 `recover` 调用者不能识别捕获到的异常, 应该避免用 `nil` 为参数抛出异常:

```go
func main() {
    defer func() {
        if r := recover(); r != nil { ... }
        // 虽然总是返回nil, 但是可以恢复异常状态
    }()

    // 警告: 用`nil`为参数抛出异常
    panic(nil)
}
```

当希望将捕获到的异常转为错误时，如果希望忠实返回原始的信息，需要针对不同的类型分别处理：

```go
func foo() (err error) {
    defer func() {
        if r := recover(); r != nil {
            switch x := r.(type) {
            case string:
                err = errors.New(x)
            case error:
                err = x
            default:
                err = fmt.Errorf("Unknown panic: %v", r)
            }
        }
    }()

    panic("TODO")
}
```

基于这个代码模板，我们甚至可以模拟出不同类型的异常。通过为定义不同类型的保护接口，我们就可以区分异常的类型了：

```go
func main {
    defer func() {
        if r := recover(); r != nil {
            switch x := r.(type) {
            case runtime.Error:
                // 这是运行时错误类型异常
            case error:
                // 普通错误类型异常
            default:
                // 其他类型异常
            }
        }
    }()

    // ...
}
```

不过这样做和 Go 语言简单直接的编程哲学背道而驰了。
